<?xml version="1.0" encoding="utf-8"?>

<!--
	Collision detection:
		robot:            101
		box:              011
		table:            010
		robot_conf_plane: 100
-->

<mujoco>
	<!-- Variable that decides the size of the userdata field. 

		We need space to detect each contact (2 integers) and each contact force (6 floats) of each substep, 
		plus a single integer per substep storing the number of contacts in the substep, plus a single integer 
		identifying the current substep, resulting in `(8 * nconmax + 1) * nsubsteps + 1` integers.

		The number below is computed for `nsubsteps=20` and `nconmax=100`.
	-->
	<size nuserdata="16021"/>
	
	<compiler angle="radian" coordinate="local" meshdir="../stls/fetch" texturedir="../textures"></compiler>
	<option timestep="0.002">
		<flag warmstart="enable"></flag>
	</option>

	<include file="shared_rot_table.xml"></include>
	
	<worldbody>
		<geom name="floor0" pos="0.8 0.75 0" size="0.85 0.7 1" type="plane" condim="3" material="floor_mat"></geom>
		<body name="floor0" pos="0.8 0.75 0">
			<site name="target0" pos="0 0 0.5" size="0.02 0.02 0.02" rgba="1 0 0 1" type="sphere"></site>
		</body>

		<include file="robot.xml"></include>
		
		<body pos="1.37 0.75 0.21" name="table1">
			<geom size="0.38 0.2" name="table1" type="cylinder" mass="1" contype="2" conaffinity="2" material="table_mat"></geom>
			<joint name="table1:joint" damping="6" type="hinge" axis="0 0 1"></joint>
			<site name="table1" pos="0 0 0" size="0.02 0.02 0.02" rgba="0 1 0 0" type="sphere"></site>
		</body>

		<body pos="1.37 0.75 0.41" name="robot_conf_plane">
			<geom size="0.4 0.4 0.4" name="robot_conf_plane" type="plane" mass="1" contype="4" conaffinity="4" rgba="0 0 0 0"></geom>
		</body>
		
		<body name="object0" pos="0.025 0.025 0.025">
			<joint name="object0:joint" type="free" damping="0.01"></joint>
			<geom size="0.025 0.025 0.025" type="box" condim="3" name="object0" contype="3" conaffinity="3" material="block_mat" mass="2"></geom>
			<site name="object0" pos="0 0 0" size="0.02 0.02 0.02" rgba="1 0 0 1" type="sphere"></site>
		</body>

		<light directional="true" ambient="0.2 0.2 0.2" diffuse="0.8 0.8 0.8" specular="0.3 0.3 0.3" castshadow="false" pos="0 0 4" dir="0 0 -1" name="light0"></light>
	</worldbody>

	<actuator>
		<position ctrllimited="true" ctrlrange="0 0.2" joint="robot0:l_gripper_finger_joint" kp="30000" name="robot0:l_gripper_finger_joint" user="1"></position>
		<position ctrllimited="true" ctrlrange="0 0.2" joint="robot0:r_gripper_finger_joint" kp="30000" name="robot0:r_gripper_finger_joint" user="1"></position>
    	<position joint="table1:joint" kp="300" name="table1:joint" user="1"></position>
	</actuator>
</mujoco>